<?xml version="1.0"?>
<robot name="bot">
    <link name="base_link">
        <visual>
            <geometry>
                <box size="0.1 0.2 0.2"/>
            </geometry>
        </visual>
        <collision>
            <geometry>
                <box size="0.1 0.2 0.2"/>
            </geometry>
        </collision>
        <inertial>
            <mass value="1"/>
            <inertia ixx="1.0" iyy="1.0" izz="1.0"/>
        </inertial>
    </link>

    <link name="left_wheel">
        <visual>
            <geometry>
                <cylinder length="0.06" radius="0.06"/>
            </geometry>
        </visual>
        <collision>
            <geometry>
                <cylinder length="0.06" radius="0.06"/>
            </geometry>
        </collision>
        <inertial>
            <mass value="1"/>
            <inertia ixx="0.01" iyy="0.01" izz="0.01"/>
        </inertial>
    </link>

    <joint name="base_to_left_wheel" type="continuous">
        <parent link="base_link"/>
        <child link="left_wheel"/>
        <axis xyz="0 0 1"/>
        <origin rpy="1.57075 0 0" xyz="0 -0.15 -0.08"/>
    </joint>

    <link name="right_wheel">
        <visual>
            <geometry>
                <cylinder length="0.06" radius="0.06"/>
            </geometry>
        </visual>
        <collision>
            <geometry>
                <cylinder length="0.06" radius="0.06"/>
            </geometry>
        </collision>
        <inertial>
            <mass value="1"/>
            <inertia ixx="0.01" iyy="0.01" izz="0.01"/>
        </inertial>
    </link>

    <joint name="base_to_right_wheel" type="continuous">
        <parent link="base_link"/>
        <child link="right_wheel"/>
        <axis xyz="0 0 1"/>
        <origin rpy="1.57075 0 0" xyz="0 0.15 -0.08"/>
    </joint>
</robot>